{"errorMessage":"Lambda process returned with error. Result: . Output:\n","errorType":"InvocationException","stackTrace":["  File \"/opt/code/localstack/localstack/services/awslambda/lambda_api.py\", line 794, in run_lambda\n    result = LAMBDA_EXECUTOR.execute(\n","  File \"/opt/code/localstack/localstack/services/awslambda/lambda_executors.py\", line 445, in execute\n    return do_execute()\n","  File \"/opt/code/localstack/localstack/services/awslambda/lambda_executors.py\", line 435, in do_execute\n    return _run(func_arn=func_arn)\n","  File \"/opt/code/localstack/localstack/utils/cloudwatch/cloudwatch_util.py\", line 158, in wrapped\n    raise e\n","  File \"/opt/code/localstack/localstack/utils/cloudwatch/cloudwatch_util.py\", line 154, in wrapped\n    result = func(*args, **kwargs)\n","  File \"/opt/code/localstack/localstack/services/awslambda/lambda_executors.py\", line 422, in _run\n    raise e\n","  File \"/opt/code/localstack/localstack/services/awslambda/lambda_executors.py\", line 418, in _run\n    result = self._execute(lambda_function, inv_context)\n","  File \"/opt/code/localstack/localstack/services/awslambda/lambda_executors.py\", line 727, in _execute\n    result = self.run_lambda_executor(lambda_function=lambda_function, inv_context=inv_context)\n","  File \"/opt/code/localstack/localstack/services/awslambda/lambda_executors.py\", line 650, in run_lambda_executor\n    raise InvocationException(\n"]}
